<?xml version='1.0'?>
<sdf version='1.3'>
  <model name='gambit'>
    <link name='arm0'>
      <pose>0.000000 0.000000 0.000000 0.000000 0.000000 0.000000</pose>
      <inertial>
        <pose>2.000000 0.000000 0.000000 0.000000 0.000000 0.000000</pose>
        <mass>1.000000</mass>
        <inertia>
          <ixx>1.000000</ixx>
          <ixy>0.000000</ixy>
          <ixz>0.000000</ixz>
          <iyy>1.000000</iyy>
          <iyz>0.000000</iyz>
          <izz>1.000000</izz>
        </inertia>
      </inertial>
      <collision name='arm0_collision'>
        <pose>0.000000 0.000000 0.000000 1.570800 -0.000000 1.570800</pose>
        <geometry>
          <mesh>
            <scale>1.000000 1.000000 1.000000</scale>
            <uri>/home/mjyc/Projects/HIL/codes/ros/stacks/ros-pkg-nsl/trunk/gambit/gambit_driver/models/arm0.stl</uri>
          </mesh>
        </geometry>
      </collision>
      <visual name='arm0_vis'>
        <pose>0.000000 0.000000 0.000000 1.570800 -0.000000 1.570800</pose>
        <geometry>
          <mesh>
            <scale>1.000000 1.000000 1.000000</scale>
            <uri>/home/mjyc/Projects/HIL/codes/ros/stacks/ros-pkg-nsl/trunk/gambit/gambit_driver/models/arm0.stl</uri>
          </mesh>
        </geometry>
      </visual>
      <velocity_decay>
        <linear>0.000000</linear>
        <angular>0.000000</angular>
      </velocity_decay>
    </link>
    <link name='arm1'>
      <pose>0.000000 0.000000 0.000500 0.000000 0.000000 0.000000</pose>
      <inertial>
        <pose>2.000000 0.000000 0.000000 0.000000 0.000000 0.000000</pose>
        <mass>1.000000</mass>
        <inertia>
          <ixx>1.000000</ixx>
          <ixy>0.000000</ixy>
          <ixz>0.000000</ixz>
          <iyy>1.000000</iyy>
          <iyz>0.000000</iyz>
          <izz>1.000000</izz>
        </inertia>
      </inertial>
      <collision name='arm1_collision'>
        <pose>0.000000 0.000000 0.000000 1.570800 0.000000 -1.570800</pose>
        <geometry>
          <mesh>
            <scale>1.000000 1.000000 1.000000</scale>
            <uri>/home/mjyc/Projects/HIL/codes/ros/stacks/ros-pkg-nsl/trunk/gambit/gambit_driver/models/arm1.stl</uri>
          </mesh>
        </geometry>
      </collision>
      <visual name='arm1_vis'>
        <pose>0.000000 0.000000 0.000000 1.570800 0.000000 -1.570800</pose>
        <geometry>
          <mesh>
            <scale>1.000000 1.000000 1.000000</scale>
            <uri>/home/mjyc/Projects/HIL/codes/ros/stacks/ros-pkg-nsl/trunk/gambit/gambit_driver/models/arm1.stl</uri>
          </mesh>
        </geometry>
      </visual>
      <velocity_decay>
        <linear>0.000000</linear>
        <angular>0.000000</angular>
      </velocity_decay>
    </link>
    <joint name='waist' type='revolute'>
      <child>arm1</child>
      <parent>arm0</parent>
      <axis>
        <xyz>0.000000 0.000000 1.000000</xyz>
        <limit>
          <lower>-10000000000000000.000000</lower>
          <upper>10000000000000000.000000</upper>
        </limit>
        <dynamics/>
      </axis>
    </joint>
    <link name='arm2'>
      <pose>0.160000 -0.030500 0.396000 0.000000 0.000000 0.000000</pose>
      <inertial>
        <pose>2.000000 0.000000 0.000000 0.000000 0.000000 0.000000</pose>
        <mass>1.000000</mass>
        <inertia>
          <ixx>1.000000</ixx>
          <ixy>0.000000</ixy>
          <ixz>0.000000</ixz>
          <iyy>1.000000</iyy>
          <iyz>0.000000</iyz>
          <izz>1.000000</izz>
        </inertia>
      </inertial>
      <visual name='arm2_vis'>
        <pose>0.000000 0.000000 0.000000 1.570800 -0.000000 1.570800</pose>
        <geometry>
          <mesh>
            <scale>1.000000 1.000000 1.000000</scale>
            <uri>/home/mjyc/Projects/HIL/codes/ros/stacks/ros-pkg-nsl/trunk/gambit/gambit_driver/models/arm2.stl</uri>
          </mesh>
        </geometry>
      </visual>
      <velocity_decay>
        <linear>0.000000</linear>
        <angular>0.000000</angular>
      </velocity_decay>
    </link>
    <joint name='shoulder' type='revolute'>
      <child>arm2</child>
      <parent>arm1</parent>
      <axis>
        <xyz>0.000000 1.000000 0.000000</xyz>
        <limit>
          <lower>-10000000000000000.000000</lower>
          <upper>10000000000000000.000000</upper>
        </limit>
        <dynamics/>
      </axis>
    </joint>
    <link name='arm3'>
      <pose>0.160000 -0.060500 0.671000 0.000000 0.000000 0.000000</pose>
      <inertial>
        <pose>2.000000 0.000000 0.000000 0.000000 0.000000 0.000000</pose>
        <mass>1.000000</mass>
        <inertia>
          <ixx>1.000000</ixx>
          <ixy>0.000000</ixy>
          <ixz>0.000000</ixz>
          <iyy>1.000000</iyy>
          <iyz>0.000000</iyz>
          <izz>1.000000</izz>
        </inertia>
      </inertial>
      <visual name='arm3_vis'>
        <pose>0.000000 0.000000 0.000000 1.570800 0.000000 -1.570800</pose>
        <geometry>
          <mesh>
            <scale>1.000000 1.000000 1.000000</scale>
            <uri>/home/mjyc/Projects/HIL/codes/ros/stacks/ros-pkg-nsl/trunk/gambit/gambit_driver/models/arm3.stl</uri>
          </mesh>
        </geometry>
      </visual>
      <velocity_decay>
        <linear>0.000000</linear>
        <angular>0.000000</angular>
      </velocity_decay>
    </link>
    <joint name='elbow' type='revolute'>
      <child>arm3</child>
      <parent>arm2</parent>
      <axis>
        <xyz>0.000000 1.000000 0.000000</xyz>
        <limit>
          <lower>-10000000000000000.000000</lower>
          <upper>10000000000000000.000000</upper>
        </limit>
        <dynamics/>
      </axis>
    </joint>
    <link name='wrist1'>
      <pose>0.160000 -0.097500 0.931000 0.000000 0.000000 0.000000</pose>
      <inertial>
        <pose>2.000000 0.000000 0.000000 0.000000 0.000000 0.000000</pose>
        <mass>1.000000</mass>
        <inertia>
          <ixx>1.000000</ixx>
          <ixy>0.000000</ixy>
          <ixz>0.000000</ixz>
          <iyy>1.000000</iyy>
          <iyz>0.000000</iyz>
          <izz>1.000000</izz>
        </inertia>
      </inertial>
      <visual name='wrist1_vis'>
        <pose>0.000000 0.000000 0.000000 3.141590 0.000000 1.570800</pose>
        <geometry>
          <mesh>
            <scale>1.000000 1.000000 1.000000</scale>
            <uri>/home/mjyc/Projects/HIL/codes/ros/stacks/ros-pkg-nsl/trunk/gambit/gambit_driver/models/wrist1.stl</uri>
          </mesh>
        </geometry>
      </visual>
      <velocity_decay>
        <linear>0.000000</linear>
        <angular>0.000000</angular>
      </velocity_decay>
    </link>
    <joint name='wrist_roll' type='revolute'>
      <child>wrist1</child>
      <parent>arm3</parent>
      <axis>
        <xyz>0.000000 0.000000 1.000000</xyz>
        <limit>
          <lower>-2.617000</lower>
          <upper>2.617000</upper>
        </limit>
        <dynamics/>
      </axis>
    </joint>
    <link name='wrist2'>
      <pose>0.160000 -0.097500 0.931000 0.000000 0.000000 0.000000</pose>
      <inertial>
        <pose>2.000000 0.000000 0.000000 0.000000 0.000000 0.000000</pose>
        <mass>1.000000</mass>
        <inertia>
          <ixx>1.000000</ixx>
          <ixy>0.000000</ixy>
          <ixz>0.000000</ixz>
          <iyy>1.000000</iyy>
          <iyz>0.000000</iyz>
          <izz>1.000000</izz>
        </inertia>
      </inertial>
      <collision name='wrist2_collision'>
        <pose>0.000000 0.000000 0.000000 0.000000 0.000000 1.570800</pose>
        <geometry>
          <mesh>
            <scale>1.000000 1.000000 1.000000</scale>
            <uri>/home/mjyc/Projects/HIL/codes/ros/stacks/ros-pkg-nsl/trunk/gambit/gambit_driver/models/wrist2.stl</uri>
          </mesh>
        </geometry>
      </collision>
      <visual name='wrist2_vis'>
        <pose>0.000000 0.000000 0.000000 0.000000 0.000000 1.570800</pose>
        <geometry>
          <mesh>
            <scale>1.000000 1.000000 1.000000</scale>
            <uri>/home/mjyc/Projects/HIL/codes/ros/stacks/ros-pkg-nsl/trunk/gambit/gambit_driver/models/wrist2.stl</uri>
          </mesh>
        </geometry>
      </visual>
      <velocity_decay>
        <linear>0.000000</linear>
        <angular>0.000000</angular>
      </velocity_decay>
    </link>
    <joint name='wrist_pitch' type='revolute'>
      <child>wrist2</child>
      <parent>wrist1</parent>
      <axis>
        <xyz>0.000000 1.000000 0.000000</xyz>
        <limit>
          <lower>-1.570000</lower>
          <upper>1.570000</upper>
        </limit>
        <dynamics/>
      </axis>
    </joint>
    <link name='wrist3'>
      <pose>0.160000 -0.097500 0.931000 0.000000 0.000000 0.000000</pose>
      <inertial>
        <pose>2.000000 0.000000 0.000000 0.000000 0.000000 0.000000</pose>
        <mass>1.000000</mass>
        <inertia>
          <ixx>1.000000</ixx>
          <ixy>0.000000</ixy>
          <ixz>0.000000</ixz>
          <iyy>1.000000</iyy>
          <iyz>0.000000</iyz>
          <izz>1.000000</izz>
        </inertia>
      </inertial>
      <collision name='wrist3_collision'>
        <pose>0.000000 0.000000 0.000000 0.000000 0.000000 1.570800</pose>
        <geometry>
          <mesh>
            <scale>1.000000 1.000000 1.000000</scale>
            <uri>/home/mjyc/Projects/HIL/codes/ros/stacks/ros-pkg-nsl/trunk/gambit/gambit_driver/models/wrist3.stl</uri>
          </mesh>
        </geometry>
      </collision>
      <visual name='wrist3_vis'>
        <pose>0.000000 0.000000 0.000000 0.000000 0.000000 1.570800</pose>
        <geometry>
          <mesh>
            <scale>1.000000 1.000000 1.000000</scale>
            <uri>/home/mjyc/Projects/HIL/codes/ros/stacks/ros-pkg-nsl/trunk/gambit/gambit_driver/models/wrist3.stl</uri>
          </mesh>
        </geometry>
      </visual>
      <velocity_decay>
        <linear>0.000000</linear>
        <angular>0.000000</angular>
      </velocity_decay>
    </link>
    <joint name='wrist_yaw' type='revolute'>
      <child>wrist3</child>
      <parent>wrist2</parent>
      <axis>
        <xyz>0.000000 0.000000 1.000000</xyz>
        <limit>
          <lower>-2.617000</lower>
          <upper>2.617000</upper>
        </limit>
        <dynamics/>
      </axis>
    </joint>
    <link name='gripper_left'>
      <pose>0.160000 -0.097500 1.011000 0.000000 0.000000 0.000000</pose>
      <inertial>
        <pose>2.000000 0.000000 0.000000 0.000000 0.000000 0.000000</pose>
        <mass>1.000000</mass>
        <inertia>
          <ixx>1.000000</ixx>
          <ixy>0.000000</ixy>
          <ixz>0.000000</ixz>
          <iyy>1.000000</iyy>
          <iyz>0.000000</iyz>
          <izz>1.000000</izz>
        </inertia>
      </inertial>
      <collision name='gripper_left_collision'>
        <pose>-0.012000 -0.020000 0.040000 3.141590 0.000003 1.570790</pose>
        <geometry>
          <mesh>
            <scale>1.000000 1.000000 1.000000</scale>
            <uri>/home/mjyc/Projects/HIL/codes/ros/stacks/ros-pkg-nsl/trunk/gambit/gambit_driver/models/finger_jaw.stl</uri>
          </mesh>
        </geometry>
      </collision>
      <visual name='gripper_left_vis'>
        <pose>-0.012000 -0.020000 0.040000 3.141590 0.000003 1.570790</pose>
        <geometry>
          <mesh>
            <scale>1.000000 1.000000 1.000000</scale>
            <uri>/home/mjyc/Projects/HIL/codes/ros/stacks/ros-pkg-nsl/trunk/gambit/gambit_driver/models/finger_jaw.stl</uri>
          </mesh>
        </geometry>
      </visual>
      <velocity_decay>
        <linear>0.000000</linear>
        <angular>0.000000</angular>
      </velocity_decay>
    </link>
    <joint name='gripper_left' type='prismatic'>
      <child>gripper_left</child>
      <parent>wrist3</parent>
      <axis>
        <xyz>0.000000 1.000000 0.000000</xyz>
        <limit>
          <lower>-0.100000</lower>
          <upper>0.100000</upper>
        </limit>
        <dynamics/>
      </axis>
    </joint>
    <link name='gripper_right'>
      <pose>0.160000 -0.097500 1.011000 0.000000 0.000000 0.000000</pose>
      <inertial>
        <pose>2.000000 0.000000 0.000000 0.000000 0.000000 0.000000</pose>
        <mass>1.000000</mass>
        <inertia>
          <ixx>1.000000</ixx>
          <ixy>0.000000</ixy>
          <ixz>0.000000</ixz>
          <iyy>1.000000</iyy>
          <iyz>0.000000</iyz>
          <izz>1.000000</izz>
        </inertia>
      </inertial>
      <collision name='gripper_right_collision'>
        <pose>0.012000 0.020000 0.040000 3.141590 0.000003 -1.570790</pose>
        <geometry>
          <mesh>
            <scale>1.000000 1.000000 1.000000</scale>
            <uri>/home/mjyc/Projects/HIL/codes/ros/stacks/ros-pkg-nsl/trunk/gambit/gambit_driver/models/finger_jaw.stl</uri>
          </mesh>
        </geometry>
      </collision>
      <visual name='gripper_right_vis'>
        <pose>0.012000 0.020000 0.040000 3.141590 0.000003 -1.570790</pose>
        <geometry>
          <mesh>
            <scale>1.000000 1.000000 1.000000</scale>
            <uri>/home/mjyc/Projects/HIL/codes/ros/stacks/ros-pkg-nsl/trunk/gambit/gambit_driver/models/finger_jaw.stl</uri>
          </mesh>
        </geometry>
      </visual>
      <velocity_decay>
        <linear>0.000000</linear>
        <angular>0.000000</angular>
      </velocity_decay>
    </link>
    <joint name='gripper_right' type='prismatic'>
      <child>gripper_right</child>
      <parent>wrist3</parent>
      <axis>
        <xyz>0.000000 1.000000 0.000000</xyz>
        <limit>
          <lower>-0.100000</lower>
          <upper>0.100000</upper>
        </limit>
        <dynamics/>
      </axis>
    </joint>
    <static>1</static>
  </model>
</sdf>
